Workbook
Name COD: WACC!$J$58
Name COE: WACC!$J$56
Name Cost_of_Debt: WACC!$J$58
Name Taper_rate: WACC!$C$17
Name Tax_rate: WACC!$C$21
Name UPDATE: 'Data Sheet'!$E$1
Name WACC: WACC!$J$61

Sheet HistoricalFS
B2: ='Dupont Analysis'!B3 -> TRENT LTD
B3: ='Dupont Analysis'!B4 -> ( TRENT | BSE Code: 500251)
B5: ₹ in Crores
B6: ="Historical Financial Statement - "&'Data Sheet'!B1 -> Historical Financial Statement - TRENT LTD
B7: Years | C7: ='Data Sheet'!B16 -> 42460 | D7: ='Data Sheet'!C16 -> 42825 | E7: ='Data Sheet'!D16 -> 43190 | F7: ='Data Sheet'!E16 -> 43555 | G7: ='Data Sheet'!F16 -> 43921 | H7: ='Data Sheet'!G16 -> 44286 | I7: ='Data Sheet'!H16 -> 44651 | J7: ='Data Sheet'!I16 -> 45016 | ... L7: ='Data Sheet'!K16 -> 45747 | M7: LTM
A9: # | B9: Income Statement
B10: Sales | C10: =IFERROR('Data Sheet'!B17,0) -> 1686.17 | D10: =IFERROR('Data Sheet'!C17,0) -> 1812.44 | E10: =IFERROR('Data Sheet'!D17,0) -> 2157.46 | F10: =IFERROR('Data Sheet'!E17,0) -> 2630.24 | G10: =IFERROR('Data Sheet'!F17,0) -> 3485.98 | H10: =IFERROR('Data Sheet'!G17,0) -> 2592.96 | I10: =IFERROR('Data Sheet'!H17,0) -> 4498.02 | J10: =IFERROR('Data Sheet'!I17,0) -> 8242.02 | ... L10: =IFERROR('Data Sheet'!K17,0) -> 17134.61 | M10: =IFERROR(SUM('Data Sheet'!H42:K42),0) -> 19263.16
B11: Sales Growth | C11: - | D11: =D10/C10-1 -> 0.074885688 | E11: =E10/D10-1 -> 0.19036216 | F11: =F10/E10-1 -> 0.21913732 | G11: =G10/F10-1 -> 0.32534674 | H11: =H10/G10-1 -> -0.25617473 | I11: =I10/H10-1 -> 0.73470474 | J11: =J10/I10-1 -> 0.83236624 | K11: =K10/J10-1 -> 0.50146566 | ... M11: =M10/L10-1 -> 0.12422518
B13: COGS | C13: =IFERROR(SUM('Data Sheet'!B18,-'Data Sheet'!B19,'Data Sheet'!B20:B21),0) -> 920.95 | D13: =IFERROR(SUM('Data Sheet'!C18,-'Data Sheet'!C19,'Data Sheet'!C20:C21),0) -> 1014.55 | E13: =IFERROR(SUM('Data Sheet'!D18,-'Data Sheet'!D19,'Data Sheet'!D20:D21),0) -> 1175.04 | F13: =IFERROR(SUM('Data Sheet'!E18,-'Data Sheet'!E19,'Data Sheet'!E20:E21),0) -> 1492.71 | G13: =IFERROR(SUM('Data Sheet'!F18,-'Data Sheet'!F19,'Data Sheet'!F20:F21),0) -> 2045.9 | H13: =IFERROR(SUM('Data Sheet'!G18,-'Data Sheet'!G19,'Data Sheet'!G20:G21),0) -> 1675.41 | I13: =IFERROR(SUM('Data Sheet'!H18,-'Data Sheet'!H19,'Data Sheet'!H20:H21),0) -> 2680.57 | J13: =IFERROR(SUM('Data Sheet'!I18,-'Data Sheet'!I19,'Data Sheet'!I20:I21),0) -> 5076.01 | ... L13: =IFERROR(SUM('Data Sheet'!K18,-'Data Sheet'!K19,'Data Sheet'!K20:K21),0) -> 10408.8 | M13: =IFERROR(SUM('Data Sheet'!H43:K43),0) -> 15867.34
B14: COGS % Sales | C14: =C13/C10 -> 0.54617862 | D14: =D13/D10 -> 0.55977025 | E14: =E13/E10 -> 0.54464046 | F14: =F13/F10 -> 0.56751855 | G14: =G13/G10 -> 0.58689379 | H14: =H13/H10 -> 0.646138 | I14: =I13/I10 -> 0.59594444 | J14: =J13/J10 -> 0.61586965 | ... M14: =M13/M10 -> 0.82371428
B16: Gross Profit | C16: =C10-C13 -> 765.22 | D16: =D10-D13 -> 797.89 | E16: =E10-E13 -> 982.42 | F16: =F10-F13 -> 1137.53 | G16: =G10-G13 -> 1440.08 | H16: =H10-H13 -> 917.55 | I16: =I10-I13 -> 1817.45 | J16: =J10-J13 -> 3166.01 | ... M16: =M10-M13 -> 3395.82
B17: Gross Margin | C17: =C16/C10 -> 0.45382138 | D17: =D16/D10 -> 0.44022975 | E17: =E16/E10 -> 0.45535954 | F17: =F16/F10 -> 0.43248145 | G17: =G16/G10 -> 0.41310621 | H17: =H16/H10 -> 0.353862 | I17: =I16/I10 -> 0.40405556 | J17: =J16/J10 -> 0.38413035 | ... M17: =M16/M10 -> 0.17628572
B19: Selling & General Expenses | C19: =IFERROR(SUM('Data Sheet'!B22:B24),0) -> 675.46 | D19: =IFERROR(SUM('Data Sheet'!C22:C24),0) -> 664.36 | E19: =IFERROR(SUM('Data Sheet'!D22:D24),0) -> 773.92 | F19: =IFERROR(SUM('Data Sheet'!E22:E24),0) -> 896.89 | G19: =IFERROR(SUM('Data Sheet'!F22:F24),0) -> 911.11 | H19: =IFERROR(SUM('Data Sheet'!G22:G24),0) -> 803.68 | I19: =IFERROR(SUM('Data Sheet'!H22:H24),0) -> 1222.73 | J19: =IFERROR(SUM('Data Sheet'!I22:I24),0) -> 2051.86 | ... L19: =IFERROR(SUM('Data Sheet'!K22:K24),0) -> 3905.85 | M19: =IFERROR(SUM('Data Sheet'!L23:L24),0) -> 0
B20: S&G Exp % Sales | C20: =C19/C10 -> 0.40058832 | D20: =D19/D10 -> 0.36655558 | E20: =E19/E10 -> 0.35871812 | F20: =F19/F10 -> 0.3409917 | G20: =G19/G10 -> 0.26136409 | H20: =H19/H10 -> 0.30994693 | I20: =I19/I10 -> 0.27183739 | J20: =J19/J10 -> 0.24895111 | ... M20: =M19/M10 -> 0 | N20: =IFERROR((HistoricalFS!C22-HistoricalFS!C31)/(SUM(HistoricalFS!C57:C59)),0) -> 0.022545985
B22: EBITDA | C22: =C16-C19 -> 89.76 | D22: =D16-D19 -> 133.53 | E22: =E16-E19 -> 208.5 | F22: =F16-F19 -> 240.64 | G22: =G16-G19 -> 528.97 | H22: =H16-H19 -> 113.87 | I22: =I16-I19 -> 594.72 | J22: =J16-J19 -> 1114.15 | ... M22: =M16-M19 -> 3395.82 | V22: =I40+I37+I25 -> 269.88 | W22: =J40+J37+J25 -> 705.16
B23: EBITDA Margin | C23: =C22/C10 -> 0.053233067 | D23: =D22/D10 -> 0.073674163 | E23: =E22/E10 -> 0.096641421 | F23: =F22/F10 -> 0.09148975 | G23: =G22/G10 -> 0.15174212 | H23: =H22/H10 -> 0.043915062 | I23: =I22/I10 -> 0.13221818 | J23: =J22/J10 -> 0.13517924 | ... M23: =M22/M10 -> 0.17628572
B25: Depreciation | C25: =IFERROR('Data Sheet'!B26,0) -> 38.59 | D25: =IFERROR('Data Sheet'!C26,0) -> 41.29 | E25: =IFERROR('Data Sheet'!D26,0) -> 45.53 | F25: =IFERROR('Data Sheet'!E26,0) -> 51.67 | G25: =IFERROR('Data Sheet'!F26,0) -> 247.24 | H25: =IFERROR('Data Sheet'!G26,0) -> 257.3 | I25: =IFERROR('Data Sheet'!H26,0) -> 310.82 | J25: =IFERROR('Data Sheet'!I26,0) -> 493.69 | ... M25: =IFERROR('Data Sheet'!L26,0) -> 0
B26: Depreciation%Sales | C26: =C25/C10 -> 0.022886186 | D26: =D25/D10 -> 0.022781444 | E26: =E25/E10 -> 0.02110352 | F26: =F25/F10 -> 0.019644595 | G26: =G25/G10 -> 0.070924102 | H26: =H25/H10 -> 0.099230223 | I26: =I25/I10 -> 0.069101516 | J26: =J25/J10 -> 0.059899151 | ... M26: =M25/M10 -> 0
B28: EBIT | C28: =C22-C25 -> 51.17 | D28: =D22-D25 -> 92.24 | E28: =E22-E25 -> 162.97 | F28: =F22-F25 -> 188.97 | G28: =G22-G25 -> 281.73 | H28: =H22-H25 -> -143.43 | I28: =I22-I25 -> 283.9 | J28: =J22-J25 -> 620.46 | ... M28: =M22-M25 -> 3395.82
B29: EBIT margin | C29: =C28/C10 -> 0.030346881 | D29: =D28/D10 -> 0.050892719 | E29: =E28/E10 -> 0.075537901 | F29: =F28/F10 -> 0.071845155 | G29: =G28/G10 -> 0.08081802 | H29: =H28/H10 -> -0.055315161 | I29: =I28/I10 -> 0.06311666 | J29: =J28/J10 -> 0.075280089 | ... M29: =M28/M10 -> 0.17628572
B31: Intrest | C31: =IFERROR('Data Sheet'!B27,0) -> 47.73 | D31: =IFERROR('Data Sheet'!C27,0) -> 45.55 | E31: =IFERROR('Data Sheet'!D27,0) -> 43.78 | F31: =IFERROR('Data Sheet'!E27,0) -> 50.64 | G31: =IFERROR('Data Sheet'!F27,0) -> 263.37 | H31: =IFERROR('Data Sheet'!G27,0) -> 260.79 | I31: =IFERROR('Data Sheet'!H27,0) -> 324.84 | J31: =IFERROR('Data Sheet'!I27,0) -> 408.99 | ... M31: =IFERROR('Data Sheet'!L27,0) -> 0
B32: Intrest%Sales | C32: =C31/C10 -> 0.028306754 | D32: =D31/D10 -> 0.025131866 | E32: =E31/E10 -> 0.020292381 | F32: =F31/F10 -> 0.019252996 | G32: =G31/G10 -> 0.075551208 | H32: =H31/H10 -> 0.10057618 | I32: =I31/I10 -> 0.072218443 | J32: =J31/J10 -> 0.049622544 | ... M32: =M31/M10 -> 0
B34: EBT | C34: =C28-C31 -> 3.44 | D34: =D28-D31 -> 46.69 | E34: =E28-E31 -> 119.19 | F34: =F28-F31 -> 138.33 | G34: =G28-G31 -> 18.36 | H34: =H28-H31 -> -404.22 | I34: =I28-I31 -> -40.94 | J34: =J28-J31 -> 211.47 | ... M34: =M28-M31 -> 3395.82
B35: EBT % Sales | C35: =C34/C10 -> 0.0020401264 | D35: =D34/D10 -> 0.025760853 | E35: =E34/E10 -> 0.05524552 | F35: =F34/F10 -> 0.052592159 | G35: =G34/G10 -> 0.0052668116 | H35: =H34/H10 -> -0.15589134 | I35: =I34/I10 -> -0.0091017826 | J35: =J34/J10 -> 0.025657545 | ... M35: =M34/M10 -> 0.17628572
B37: Tax | C37: =IFERROR('Data Sheet'!B29,0) -> 34.71 | D37: =IFERROR('Data Sheet'!C29,0) -> 43.05 | E37: =IFERROR('Data Sheet'!D29,0) -> 59.62 | F37: =IFERROR('Data Sheet'!E29,0) -> 73.61 | G37: =IFERROR('Data Sheet'!F29,0) -> 59.01 | H37: =IFERROR('Data Sheet'!G29,0) -> -23.69 | I37: =IFERROR('Data Sheet'!H29,0) -> 76.62 | J37: =IFERROR('Data Sheet'!I29,0) -> 158.44 | ... L37: =IFERROR('Data Sheet'!K29,0) -> 495.33 | M37: =IFERROR(SUM('Data Sheet'!H48:K48),0) -> 513.53
B38: Effective tax Rate | C38: =C37/C34 -> 10.090116 | D38: =D37/D34 -> 0.92203898 | E38: =E37/E34 -> 0.50020975 | F38: =F37/F34 -> 0.5321333 | G38: =G37/G34 -> 3.2140523 | H38: =H37/H34 -> 0.058606699 | I38: =I37/I34 -> -1.8715193 | J38: =J37/J34 -> 0.74923157 | ... M38: =M37/M34 -> 0.15122415
B40: Net Profit | C40: =IFERROR(C34-C37,0) -> -31.27 | D40: =IFERROR(D34-D37,0) -> 3.64 | E40: =IFERROR(E34-E37,0) -> 59.57 | F40: =IFERROR(F34-F37,0) -> 64.72 | G40: =IFERROR(G34-G37,0) -> -40.65 | H40: =IFERROR(H34-H37,0) -> -380.53 | I40: =IFERROR(I34-I37,0) -> -117.56 | J40: =IFERROR(J34-J37,0) -> 53.03 | ... M40: =IFERROR(M34-M37,0) -> 2882.29
B41: Net profit Margin | C41: =C40/C10 -> -0.018544987 | D41: =D40/D10 -> 0.0020083423 | E41: =E40/E10 -> 0.027611172 | F41: =F40/F10 -> 0.02460612 | G41: =G40/G10 -> -0.011660996 | H41: =H40/H10 -> -0.14675506 | I41: =I40/I10 -> -0.026135944 | J41: =J40/J10 -> 0.0064341023 | ... M41: =M40/M10 -> 0.14962706
B43: No. of Equity Shares | C43: ='Data Sheet'!B100 -> 33.23 | D43: ='Data Sheet'!C100 -> 33.23 | E43: ='Data Sheet'!D100 -> 33.23 | F43: ='Data Sheet'!E100 -> 33.23 | G43: ='Data Sheet'!F100 -> 35.55 | H43: ='Data Sheet'!G100 -> 35.55 | I43: ='Data Sheet'!H100 -> 35.55 | J43: ='Data Sheet'!I100 -> 35.55 | ... L43: ='Data Sheet'!K100 -> 35.55 | M43: =L43 -> 35.55
B45: EPS | C45: =IFERROR(C40/C43,0) -> -0.94101715 | D45: =IFERROR(D40/D43,0) -> 0.10953957 | E45: =IFERROR(E40/E43,0) -> 1.7926572 | F45: =IFERROR(F40/F43,0) -> 1.9476377 | G45: =IFERROR(G40/G43,0) -> -1.1434599 | H45: =IFERROR(H40/H43,0) -> -10.704079 | I45: =IFERROR(I40/I43,0) -> -3.3068917 | J45: =IFERROR(J40/J43,0) -> 1.4917018 | ... M45: =IFERROR(M40/M43,0) -> 81.077075
B46: EPS Growth % | C46: - | D46: =IFERROR(D45/C45-1,0) -> -1.1164055 | E46: =IFERROR(E45/D45-1,0) -> 15.365385 | F46: =IFERROR(F45/E45-1,0) -> 0.086452913 | G46: =IFERROR(G45/F45-1,0) -> -1.5871009 | H46: =IFERROR(H45/G45-1,0) -> 8.3611316 | I46: =IFERROR(I45/H45-1,0) -> -0.69106247 | J46: =IFERROR(J45/I45-1,0) -> -1.4510888 | K46: =IFERROR(K45/J45-1,0) -> 8.2127098 | ... M46: =IFERROR(M45/L45-1,0) -> 1.3445642
B48: Divided per Share | C48: =IFERROR('Data Sheet'!B31/HistoricalFS!C43,0) -> 0.90009028 | D48: =IFERROR('Data Sheet'!C31/HistoricalFS!D43,0) -> 1 | E48: =IFERROR('Data Sheet'!D31/HistoricalFS!E43,0) -> 1.1498646 | F48: =IFERROR('Data Sheet'!E31/HistoricalFS!F43,0) -> 1.3000301 | G48: =IFERROR('Data Sheet'!F31/HistoricalFS!G43,0) -> 1 | H48: =IFERROR('Data Sheet'!G31/HistoricalFS!H43,0) -> 0.6 | I48: =IFERROR('Data Sheet'!H31/HistoricalFS!I43,0) -> 1.7001406 | J48: =IFERROR('Data Sheet'!I31/HistoricalFS!J43,0) -> 2.2 | ... M48: =IFERROR('Data Sheet'!L31/HistoricalFS!M43,0) -> 0
B49: Divided Payout Ratio | C49: =IFERROR(C48/C45,0) -> -0.95650783 | D49: =IFERROR(D48/D45,0) -> 9.1291209 | E49: =IFERROR(E48/E45,0) -> 0.64143025 | F49: =IFERROR(F48/F45,0) -> 0.66749073 | G49: =IFERROR(G48/G45,0) -> -0.87453875 | H49: =IFERROR(H48/H45,0) -> -0.056053399 | I49: =IFERROR(I48/I45,0) -> -0.51412045 | J49: =IFERROR(J48/J45,0) -> 1.4748256 | ... M49: =IFERROR(M48/M45,0) -> 0
B51: Retained Earning | C51: =IFERROR(IF(C45>C48,1-C49,0),0) -> 0 | D51: =IFERROR(IF(D45>D48,1-D49,0),0) -> 0 | E51: =IFERROR(IF(E45>E48,1-E49,0),0) -> 0.35856975 | F51: =IFERROR(IF(F45>F48,1-F49,0),0) -> 0.33250927 | G51: =IFERROR(IF(G45>G48,1-G49,0),0) -> 0 | H51: =IFERROR(IF(H45>H48,1-H49,0),0) -> 0 | I51: =IFERROR(IF(I45>I48,1-I49,0),0) -> 0 | J51: =IFERROR(IF(J45>J48,1-J49,0),0) -> 0 | ... M51: =IFERROR(IF(M45>M48,1-M49,0),0) -> 1
A53: # | B53: Balance Sheet
B55: Particulars | C55: =C7 -> 42460 | D55: =D7 -> 42825 | E55: =E7 -> 43190 | F55: =F7 -> 43555 | G55: =G7 -> 43921 | H55: =H7 -> 44286 | I55: =I7 -> 44651 | J55: =J7 -> 45016 | ... L55: =L7 -> 45747
B57: Equity Share Capital | C57: =IFERROR('Data Sheet'!B57,0) -> 33.23 | D57: =IFERROR('Data Sheet'!C57,0) -> 33.23 | E57: =IFERROR('Data Sheet'!D57,0) -> 33.23 | F57: =IFERROR('Data Sheet'!E57,0) -> 33.23 | G57: =IFERROR('Data Sheet'!F57,0) -> 35.55 | H57: =IFERROR('Data Sheet'!G57,0) -> 35.55 | I57: =IFERROR('Data Sheet'!H57,0) -> 35.55 | J57: =IFERROR('Data Sheet'!I57,0) -> 35.55 | ... L57: =IFERROR('Data Sheet'!K57,0) -> 35.55
B58: Reserves | C58: =IFERROR('Data Sheet'!B58,0) -> 1431.16 | D58: =IFERROR('Data Sheet'!C58,0) -> 1514.46 | E58: =IFERROR('Data Sheet'!D58,0) -> 1562.14 | F58: =IFERROR('Data Sheet'!E58,0) -> 1613.28 | G58: =IFERROR('Data Sheet'!F58,0) -> 2352.22 | H58: =IFERROR('Data Sheet'!G58,0) -> 2277.48 | I58: =IFERROR('Data Sheet'!H58,0) -> 2328.45 | J58: =IFERROR('Data Sheet'!I58,0) -> 2559.94 | ... L58: =IFERROR('Data Sheet'!K58,0) -> 5426.19
B59: Borrowings | C59: =IFERROR('Data Sheet'!B59,0) -> 399.8 | D59: =IFERROR('Data Sheet'!C59,0) -> 391.74 | E59: =IFERROR('Data Sheet'!D59,0) -> 391.43 | F59: =IFERROR('Data Sheet'!E59,0) -> 494.14 | G59: =IFERROR('Data Sheet'!F59,0) -> 299.74 | H59: =IFERROR('Data Sheet'!G59,0) -> 299.93 | I59: =IFERROR('Data Sheet'!H59,0) -> 4725.36 | J59: =IFERROR('Data Sheet'!I59,0) -> 4464.14 | ... L59: =IFERROR('Data Sheet'!K59,0) -> 2237.19
B60: Other Liabilities | C60: =IFERROR('Data Sheet'!B60,0) -> 292.4 | D60: =IFERROR('Data Sheet'!C60,0) -> 282.82 | E60: =IFERROR('Data Sheet'!D60,0) -> 349.06 | F60: =IFERROR('Data Sheet'!E60,0) -> 418.11 | G60: =IFERROR('Data Sheet'!F60,0) -> 2819.17 | H60: =IFERROR('Data Sheet'!G60,0) -> 3110.77 | I60: =IFERROR('Data Sheet'!H60,0) -> 636.66 | J60: =IFERROR('Data Sheet'!I60,0) -> 1021.9 | ... L60: =IFERROR('Data Sheet'!K60,0) -> 1720.71
...

Sheet Ration Analysis
B4: =HistoricalFS!B2 -> TRENT LTD
B5: =HistoricalFS!B3 -> ( TRENT | BSE Code: 500251)
B7: ="Ration Analysis -"&'Data Sheet'!B1 -> Ration Analysis -TRENT LTD
B8: Years | C8: =HistoricalFS!C7 -> 42460 | D8: =HistoricalFS!D7 -> 42825 | E8: =HistoricalFS!E7 -> 43190 | F8: =HistoricalFS!F7 -> 43555 | G8: =HistoricalFS!G7 -> 43921 | H8: =HistoricalFS!H7 -> 44286 | I8: =HistoricalFS!I7 -> 44651 | J8: =HistoricalFS!J7 -> 45016 | ... L8: =HistoricalFS!L7 -> 45747 | M8: Trend | N8: Mean | O8: Median
B10: Growth Ratio
B11: Sales Growth | D11: =IFERROR(HistoricalFS!D11,0) -> 0.074885688 | E11: =IFERROR(HistoricalFS!E11,0) -> 0.19036216 | F11: =IFERROR(HistoricalFS!F11,0) -> 0.21913732 | G11: =IFERROR(HistoricalFS!G11,0) -> 0.32534674 | H11: =IFERROR(HistoricalFS!H11,0) -> -0.25617473 | I11: =IFERROR(HistoricalFS!I11,0) -> 0.73470474 | J11: =IFERROR(HistoricalFS!J11,0) -> 0.83236624 | K11: =IFERROR(HistoricalFS!K11,0) -> 0.50146566 | L11: =IFERROR(HistoricalFS!L11,0) -> 0.38460264 | N11: =IFERROR(AVERAGE(D11:L11),0) -> 0.33407738 | O11: =IFERROR(MEDIAN(C11:L11),0) -> 0.32534674
B12: EBITDA Growth | D12: =IFERROR(HistoricalFS!D22/HistoricalFS!C22-1,0) -> 0.48763369 | E12: =IFERROR(HistoricalFS!E22/HistoricalFS!D22-1,0) -> 0.56144687 | F12: =IFERROR(HistoricalFS!F22/HistoricalFS!E22-1,0) -> 0.15414868 | G12: =IFERROR(HistoricalFS!G22/HistoricalFS!F22-1,0) -> 1.1981799 | H12: =IFERROR(HistoricalFS!H22/HistoricalFS!G22-1,0) -> -0.78473259 | I12: =IFERROR(HistoricalFS!I22/HistoricalFS!H22-1,0) -> 4.2227979 | J12: =IFERROR(HistoricalFS!J22/HistoricalFS!I22-1,0) -> 0.87340261 | K12: =IFERROR(HistoricalFS!K22/HistoricalFS!J22-1,0) -> 0.76878338 | L12: =IFERROR(HistoricalFS!L22/HistoricalFS!K22-1,0) -> 0.43095058 | N12: =IFERROR(AVERAGE(D12:L12),0) -> 0.879179 | O12: =IFERROR(MEDIAN(C12:L12),0) -> 0.56144687
B13: EBT Growth | D13: =IFERROR(HistoricalFS!D34/HistoricalFS!C34-1,0) -> 12.572674 | E13: =IFERROR(HistoricalFS!E34/HistoricalFS!D34-1,0) -> 1.552795 | F13: =IFERROR(HistoricalFS!F34/HistoricalFS!E34-1,0) -> 0.16058394 | G13: =IFERROR(HistoricalFS!G34/HistoricalFS!F34-1,0) -> -0.86727391 | H13: =IFERROR(HistoricalFS!H34/HistoricalFS!G34-1,0) -> -23.01634 | I13: =IFERROR(HistoricalFS!I34/HistoricalFS!H34-1,0) -> -0.89871852 | J13: =IFERROR(HistoricalFS!J34/HistoricalFS!I34-1,0) -> -6.1653639 | K13: =IFERROR(HistoricalFS!K34/HistoricalFS!J34-1,0) -> 3.4068662 | L13: =IFERROR(HistoricalFS!L34/HistoricalFS!K34-1,0) -> 0.85067388 | N13: =IFERROR(AVERAGE(D13:L13),0) -> -1.3782336 | O13: =IFERROR(MEDIAN(C13:L13),0) -> 0.16058394
B14: Net Profit Growth | D14: =IFERROR(HistoricalFS!D40/HistoricalFS!C40-1,0) -> -1.1164055 | E14: =IFERROR(HistoricalFS!E40/HistoricalFS!D40-1,0) -> 15.365385 | F14: =IFERROR(HistoricalFS!F40/HistoricalFS!E40-1,0) -> 0.086452913 | G14: =IFERROR(HistoricalFS!G40/HistoricalFS!F40-1,0) -> -1.6280902 | H14: =IFERROR(HistoricalFS!H40/HistoricalFS!G40-1,0) -> 8.3611316 | I14: =IFERROR(HistoricalFS!I40/HistoricalFS!H40-1,0) -> -0.69106247 | J14: =IFERROR(HistoricalFS!J40/HistoricalFS!I40-1,0) -> -1.4510888 | K14: =IFERROR(HistoricalFS!K40/HistoricalFS!J40-1,0) -> 8.2127098 | L14: =IFERROR(HistoricalFS!L40/HistoricalFS!K40-1,0) -> 1.5163238 | N14: =IFERROR(AVERAGE(D14:L14),0) -> 3.1839284 | O14: =IFERROR(MEDIAN(C14:L14),0) -> 0.086452913
B15: Dividend Growth | D15: =IFERROR(HistoricalFS!D48/HistoricalFS!C48-1,0) -> 0.11099967 | E15: =IFERROR(HistoricalFS!E48/HistoricalFS!D48-1,0) -> 0.14986458 | F15: =IFERROR(HistoricalFS!F48/HistoricalFS!E48-1,0) -> 0.13059409 | G15: =IFERROR(HistoricalFS!G48/HistoricalFS!F48-1,0) -> -0.23078704 | H15: =IFERROR(HistoricalFS!H48/HistoricalFS!G48-1,0) -> -0.4 | I15: =IFERROR(HistoricalFS!I48/HistoricalFS!H48-1,0) -> 1.8335677 | J15: =IFERROR(HistoricalFS!J48/HistoricalFS!I48-1,0) -> 0.29401059 | K15: =IFERROR(HistoricalFS!K48/HistoricalFS!J48-1,0) -> 0 | L15: =IFERROR(HistoricalFS!L48/HistoricalFS!K48-1,0) -> 0 | N15: =IFERROR(AVERAGE(D15:L15),0) -> 0.20980551 | O15: =IFERROR(MEDIAN(C15:L15),0) -> 0.11099967
B17: Profitability Ratio
B18: Gross Margin | C18: =IFERROR(HistoricalFS!C17,0) -> 0.45382138 | D18: =IFERROR(HistoricalFS!D17,0) -> 0.44022975 | E18: =IFERROR(HistoricalFS!E17,0) -> 0.45535954 | F18: =IFERROR(HistoricalFS!F17,0) -> 0.43248145 | G18: =IFERROR(HistoricalFS!G17,0) -> 0.41310621 | H18: =IFERROR(HistoricalFS!H17,0) -> 0.353862 | I18: =IFERROR(HistoricalFS!I17,0) -> 0.40405556 | J18: =IFERROR(HistoricalFS!J17,0) -> 0.38413035 | ... L18: =IFERROR(HistoricalFS!L17,0) -> 0.39252776 | N18: =IFERROR(AVERAGE(C18:L18),0) -> 0.41273458 | O18: =IFERROR(MEDIAN(C18:L18),0) -> 0.40858089
B19: EBITDA Margin | C19: =IFERROR(HistoricalFS!C23,0) -> 0.053233067 | D19: =IFERROR(HistoricalFS!D23,0) -> 0.073674163 | E19: =IFERROR(HistoricalFS!E23,0) -> 0.096641421 | F19: =IFERROR(HistoricalFS!F23,0) -> 0.09148975 | G19: =IFERROR(HistoricalFS!G23,0) -> 0.15174212 | H19: =IFERROR(HistoricalFS!H23,0) -> 0.043915062 | I19: =IFERROR(HistoricalFS!I23,0) -> 0.13221818 | J19: =IFERROR(HistoricalFS!J23,0) -> 0.13517924 | ... L19: =IFERROR(HistoricalFS!L23,0) -> 0.16457684 | N19: =IFERROR(AVERAGE(C19:L19),0) -> 0.11019161 | O19: =IFERROR(MEDIAN(C19:L19),0) -> 0.1144298
B20: EBIT Margin | C20: =IFERROR(HistoricalFS!C29,0) -> 0.030346881 | D20: =HistoricalFS!D29 -> 0.050892719 | E20: =HistoricalFS!E29 -> 0.075537901 | F20: =HistoricalFS!F29 -> 0.071845155 | G20: =HistoricalFS!G29 -> 0.08081802 | H20: =HistoricalFS!H29 -> -0.055315161 | I20: =HistoricalFS!I29 -> 0.06311666 | J20: =HistoricalFS!J29 -> 0.075280089 | K20: =HistoricalFS!K29 -> 0.10501563 | L20: =HistoricalFS!L29 -> 0.11233287 | N20: =IFERROR(AVERAGE(C20:L20),0) -> 0.060987077 | O20: =IFERROR(MEDIAN(C20:L20),0) -> 0.073562622
B21: EBT Margin | C21: =IFERROR(HistoricalFS!C35,0) -> 0.0020401264 | D21: =IFERROR(HistoricalFS!D35,0) -> 0.025760853 | E21: =IFERROR(HistoricalFS!E35,0) -> 0.05524552 | F21: =IFERROR(HistoricalFS!F35,0) -> 0.052592159 | G21: =IFERROR(HistoricalFS!G35,0) -> 0.0052668116 | H21: =IFERROR(HistoricalFS!H35,0) -> -0.15589134 | I21: =IFERROR(HistoricalFS!I35,0) -> -0.0091017826 | J21: =IFERROR(HistoricalFS!J35,0) -> 0.025657545 | ... L21: =IFERROR(HistoricalFS!L35,0) -> 0.10065476 | N21: =IFERROR(AVERAGE(C21:L21),0) -> 0.017753065 | O21: =IFERROR(MEDIAN(C21:L21),0) -> 0.025709199
B22: Net Profit Margin | C22: =IFERROR(HistoricalFS!C41,0) -> -0.018544987 | D22: =IFERROR(HistoricalFS!D41,0) -> 0.0020083423 | E22: =IFERROR(HistoricalFS!E41,0) -> 0.027611172 | F22: =IFERROR(HistoricalFS!F41,0) -> 0.02460612 | G22: =IFERROR(HistoricalFS!G41,0) -> -0.011660996 | H22: =IFERROR(HistoricalFS!H41,0) -> -0.14675506 | I22: =IFERROR(HistoricalFS!I41,0) -> -0.026135944 | J22: =IFERROR(HistoricalFS!J41,0) -> 0.0064341023 | ... L22: =IFERROR(HistoricalFS!L41,0) -> 0.071746599 | N22: =IFERROR(AVERAGE(C22:L22),0) -> -0.0031212214 | O22: =IFERROR(MEDIAN(C22:L22),0) -> 0.0042212223
B23: Return On Equity (ROE) | C23: - | D23: =HistoricalFS!D40/'Data Sheet'!C79 -> 0.0024169345 | E23: =HistoricalFS!E40/'Data Sheet'!D79 -> 0.037905735 | F23: =HistoricalFS!F40/'Data Sheet'!E79 -> 0.03992745 | G23: =HistoricalFS!G40/'Data Sheet'!F79 -> -0.020152295 | H23: =HistoricalFS!H40/'Data Sheet'!G79 -> -0.1619001 | I23: =HistoricalFS!I40/'Data Sheet'!H79 -> -0.050271219 | J23: =HistoricalFS!J40/'Data Sheet'!I79 -> 0.021385263 | K23: =HistoricalFS!K40/'Data Sheet'!J79 -> 0.14664059 | L23: =HistoricalFS!L40/'Data Sheet'!K79 -> 0.25800988 | N23: =IFERROR(AVERAGE(C23:L23),0) -> 0.030440249 | O23: =IFERROR(MEDIAN(C23:L23),0) -> 0.021385263
B24: Return On Captial Employed (ROCE) | C24: - | D24: =HistoricalFS!D28/'Data Sheet'!C82 -> 0.048501165 | E24: =HistoricalFS!E28/'Data Sheet'!D82 -> 0.083016023 | F24: =HistoricalFS!F28/'Data Sheet'!E82 -> 0.091567433 | G24: =HistoricalFS!G28/'Data Sheet'!F82 -> 0.11670284 | H24: =HistoricalFS!H28/'Data Sheet'!G82 -> -0.054119729 | I24: =HistoricalFS!I28/'Data Sheet'!H82 -> 0.058522085 | J24: =HistoricalFS!J28/'Data Sheet'!I82 -> 0.087703787 | K24: =HistoricalFS!K28/'Data Sheet'!J82 -> 0.2017925 | L24: =HistoricalFS!L28/'Data Sheet'!K82 -> 0.28473793 | N24: =IFERROR(AVERAGE(C24:L24),0) -> 0.10204711 | O24: =IFERROR(MEDIAN(C24:L24),0) -> 0.087703787
B25: Return On Assets (ROA) | C25: - | D25: =HistoricalFS!D40/'Data Sheet'!C78 -> 0.0016625408 | E25: =HistoricalFS!E40/'Data Sheet'!D78 -> 0.026138027 | F25: =HistoricalFS!F40/'Data Sheet'!E78 -> 0.026445362 | G25: =HistoricalFS!G40/'Data Sheet'!F78 -> -0.010080045 | H25: =HistoricalFS!H40/'Data Sheet'!G78 -> -0.067767784 | I25: =HistoricalFS!I40/'Data Sheet'!H78 -> -0.017481366 | J25: =HistoricalFS!J40/'Data Sheet'!I78 -> 0.0067094521 | K25: =HistoricalFS!K40/'Data Sheet'!J78 -> 0.064100377 | L25: =HistoricalFS!L40/'Data Sheet'!K78 -> 0.14828069 | N25: =IFERROR(AVERAGE(C25:L25),0) -> 0.019778584 | O25: =IFERROR(MEDIAN(C25:L25),0) -> 0.0067094521
B27: Leverage Ratio
B28: Interest Coverage Ratio | C28: =HistoricalFS!C28/HistoricalFS!C31 -> 1.0720721 | D28: =HistoricalFS!D28/HistoricalFS!D31 -> 2.0250274 | E28: =HistoricalFS!E28/HistoricalFS!E31 -> 3.722476 | F28: =HistoricalFS!F28/HistoricalFS!F31 -> 3.7316351 | G28: =HistoricalFS!G28/HistoricalFS!G31 -> 1.0697118 | H28: =HistoricalFS!H28/HistoricalFS!H31 -> -0.54998274 | I28: =HistoricalFS!I28/HistoricalFS!I31 -> 0.87396872 | J28: =HistoricalFS!J28/HistoricalFS!J31 -> 1.5170542 | ... L28: =HistoricalFS!L28/HistoricalFS!L31 -> 9.6190905 | N28: =IFERROR(AVERAGE(C28:L28),0) -> 2.6615786 | O28: =IFERROR(MEDIAN(C28:L28),0) -> 1.7710408
B29: Debt to Equity Ratio | C29: =HistoricalFS!C59/SUM(HistoricalFS!C57:C58) -> 0.2730147 | D29: =HistoricalFS!D59/SUM(HistoricalFS!D57:D58) -> 0.2531127 | E29: =HistoricalFS!E59/SUM(HistoricalFS!E57:E58) -> 0.24535374 | F29: =HistoricalFS!F59/SUM(HistoricalFS!F57:F58) -> 0.30011357 | G29: =HistoricalFS!G59/SUM(HistoricalFS!G57:G58) -> 0.12553135 | H29: =HistoricalFS!H59/SUM(HistoricalFS!H57:H58) -> 0.12966974 | I29: =HistoricalFS!I59/SUM(HistoricalFS!I57:I58) -> 1.9988832 | J29: =HistoricalFS!J59/SUM(HistoricalFS!J57:J58) -> 1.7199604 | ... L29: =HistoricalFS!L59/SUM(HistoricalFS!L57:L58) -> 0.40961122 | N29: =IFERROR(AVERAGE(C29:L29),0) -> 0.58862001 | O29: =IFERROR(MEDIAN(C29:L29),0) -> 0.28656414
B30: Debt to Asset | C30: =HistoricalFS!C59/HistoricalFS!C74 -> 0.18538526 | D30: =HistoricalFS!D59/HistoricalFS!D74 -> 0.1762808 | E30: =HistoricalFS!E59/HistoricalFS!E74 -> 0.16757426 | F30: =HistoricalFS!F59/HistoricalFS!F74 -> 0.19311698 | G30: =HistoricalFS!G59/HistoricalFS!G74 -> 0.054432072 | H30: =HistoricalFS!H59/HistoricalFS!H74 -> 0.052401144 | I30: =HistoricalFS!I59/HistoricalFS!I74 -> 0.61161633 | J30: =HistoricalFS!J59/HistoricalFS!J74 -> 0.55238798 | ... L30: =HistoricalFS!L59/HistoricalFS!L74 -> 0.23750271 | N30: =IFERROR(AVERAGE(C30:L30),0) -> 0.24754687 | O30: =IFERROR(MEDIAN(C30:L30),0) -> 0.18925112
B31: Financial Leverage Ratio | D31: =HistoricalFS!D72/'Data Sheet'!C79 -> 0.22944942 | E31: =HistoricalFS!E72/'Data Sheet'!D79 -> 0.24987114 | F31: =HistoricalFS!F72/'Data Sheet'!E79 -> 0.35027823 | G31: =HistoricalFS!G72/'Data Sheet'!F79 -> 0.34025402 | H31: =HistoricalFS!H72/'Data Sheet'!G79 -> 0.22576157 | I31: =HistoricalFS!I72/'Data Sheet'!H79 -> 0.41565267 | J31: =HistoricalFS!J72/'Data Sheet'!I79 -> 0.59758161 | K31: =HistoricalFS!K72/'Data Sheet'!J79 -> 0.58891258 | L31: =HistoricalFS!L72/'Data Sheet'!K79 -> 0.51374052 | N31: =IFERROR(AVERAGE(D31:L31),0) -> 0.39016686 | O31: =IFERROR(MEDIAN(D31:L31),0) -> 0.35027823
B33: Efficiency Ratio
B34: Receivables Turnover Ratio | D34: =HistoricalFS!D10/'Data Sheet'!C74 -> 191.69117 | E34: =HistoricalFS!E10/'Data Sheet'!D74 -> 205.27688 | F34: =HistoricalFS!F10/'Data Sheet'!E74 -> 166.26043 | G34: =HistoricalFS!G10/'Data Sheet'!F74 -> 207.12894 | H34: =HistoricalFS!H10/'Data Sheet'!G74 -> 136.86778 | I34: =HistoricalFS!I10/'Data Sheet'!H74 -> 230.49039 | J34: =HistoricalFS!J10/'Data Sheet'!I74 -> 313.08718 | K34: =HistoricalFS!K10/'Data Sheet'!J74 -> 213.12512 | L34: =HistoricalFS!L10/'Data Sheet'!K74 -> 236.84581 | N34: =IFERROR(AVERAGE(C34:L34),0) -> 211.19708 | O34: =IFERROR(MEDIAN(C34:L34),0) -> 207.12894
B35: Creditor Turnover Ratio | C35: =IFERROR(HistoricalFS!C10/HistoricalFS!C60,0) -> 5.7666553 | D35: =IFERROR(HistoricalFS!D10/HistoricalFS!D60,0) -> 6.4084577 | E35: =IFERROR(HistoricalFS!E10/HistoricalFS!E60,0) -> 6.1807712 | F35: =IFERROR(HistoricalFS!F10/HistoricalFS!F60,0) -> 6.2907847 | G35: =IFERROR(HistoricalFS!G10/HistoricalFS!G60,0) -> 1.2365271 | H35: =IFERROR(HistoricalFS!H10/HistoricalFS!H60,0) -> 0.83354282 | I35: =IFERROR(HistoricalFS!I10/HistoricalFS!I60,0) -> 7.0650269 | J35: =IFERROR(HistoricalFS!J10/HistoricalFS!J60,0) -> 8.065388 | ... L35: =IFERROR(HistoricalFS!L10/HistoricalFS!L60,0) -> 9.957872 | N35: =IFERROR(AVERAGE(C35:L35),0) -> 6.1033158 | O35: =IFERROR(MEDIAN(C35:L35),0) -> 6.3496212
B36: Inventory Turnover | C36: =IFERROR(HistoricalFS!C10/HistoricalFS!C70,0) -> 6.0395071 | D36: =IFERROR(HistoricalFS!D10/HistoricalFS!D70,0) -> 5.9354205 | E36: =IFERROR(HistoricalFS!E10/HistoricalFS!E70,0) -> 6.257679 | F36: =IFERROR(HistoricalFS!F10/HistoricalFS!F70,0) -> 5.2921269 | G36: =IFERROR(HistoricalFS!G10/HistoricalFS!G70,0) -> 5.735312 | H36: =IFERROR(HistoricalFS!H10/HistoricalFS!H70,0) -> 6.0528024 | I36: =IFERROR(HistoricalFS!I10/HistoricalFS!I70,0) -> 5.1833644 | J36: =IFERROR(HistoricalFS!J10/HistoricalFS!J70,0) -> 6.0551441 | ... L36: =IFERROR(HistoricalFS!L10/HistoricalFS!L70,0) -> 8.3785775 | N36: =IFERROR(AVERAGE(C36:L36),0) -> 6.2748772 | O36: =IFERROR(MEDIAN(C36:L36),0) -> 6.0461547
B37: Fixed Asset Turnover | C37: =IFERROR(HistoricalFS!C10/HistoricalFS!C63,0) -> 3.5365045 | D37: =IFERROR(HistoricalFS!D10/HistoricalFS!D63,0) -> 3.3030927 | E37: =IFERROR(HistoricalFS!E10/HistoricalFS!E63,0) -> 3.5222112 | F37: =IFERROR(HistoricalFS!F10/HistoricalFS!F63,0) -> 3.9720922 | G37: =IFERROR(HistoricalFS!G10/HistoricalFS!G63,0) -> 1.2729849 | H37: =IFERROR(HistoricalFS!H10/HistoricalFS!H63,0) -> 0.84908737 | I37: =IFERROR(HistoricalFS!I10/HistoricalFS!I63,0) -> 0.95973935 | J37: =IFERROR(HistoricalFS!J10/HistoricalFS!J63,0) -> 1.8206563 | ... L37: =IFERROR(HistoricalFS!L10/HistoricalFS!L63,0) -> 4.3989828 | N37: =IFERROR(AVERAGE(C37:L37),0) -> 2.8686582 | O37: =IFERROR(MEDIAN(C37:L37),0) -> 3.4126519
B38: Capital Turnover Ratio | C38: =IFERROR(HistoricalFS!C10/SUM(HistoricalFS!C57:C58),0) -> 1.1514487 | D38: =IFERROR(HistoricalFS!D10/SUM(HistoricalFS!D57:D58),0) -> 1.1710614 | E38: =IFERROR(HistoricalFS!E10/SUM(HistoricalFS!E57:E58),0) -> 1.3523258 | F38: =IFERROR(HistoricalFS!F10/SUM(HistoricalFS!F57:F58),0) -> 1.5974637 | G38: =IFERROR(HistoricalFS!G10/SUM(HistoricalFS!G57:G58),0) -> 1.4599312 | H38: =IFERROR(HistoricalFS!H10/SUM(HistoricalFS!H57:H58),0) -> 1.1210231 | I38: =IFERROR(HistoricalFS!I10/SUM(HistoricalFS!I57:I58),0) -> 1.9027157 | J38: =IFERROR(HistoricalFS!J10/SUM(HistoricalFS!J57:J58),0) -> 3.175516 | ... L38: =IFERROR(HistoricalFS!L10/SUM(HistoricalFS!L57:L58),0) -> 3.1372072 | N38: =IFERROR(AVERAGE(C38:L38),0) -> 1.911095 | O38: =IFERROR(MEDIAN(C38:L38),0) -> 1.5286975
B39: Debtor Days | C39: =IFERROR(365/C34,0) -> 0 | D39: =IFERROR(365/D34,0) -> 1.9041044 | E39: =IFERROR(365/E34,0) -> 1.7780863 | F39: =IFERROR(365/F34,0) -> 2.195351 | G39: =IFERROR(365/G34,0) -> 1.7621874 | H39: =IFERROR(365/H34,0) -> 2.6668074 | I39: =IFERROR(365/I34,0) -> 1.5835801 | J39: =IFERROR(365/J34,0) -> 1.1658095 | ... L39: =IFERROR(365/L34,0) -> 1.541087 | N39: =IFERROR(AVERAGE(C39:L39),0) -> 1.6309622 | O39: =IFERROR(AVERAGE(D39:M39),0) -> 1.8121802
B40: Creditor Days | C40: =IFERROR(365/C35,0) -> 63.294923 | D40: =IFERROR(365/D35,0) -> 56.955982 | E40: =IFERROR(365/E35,0) -> 59.054119 | F40: =IFERROR(365/F35,0) -> 58.021378 | G40: =IFERROR(365/G35,0) -> 295.18157 | H40: =IFERROR(365/H35,0) -> 437.88992 | I40: =IFERROR(365/I35,0) -> 51.662932 | J40: =IFERROR(365/J35,0) -> 45.255107 | ... L40: =IFERROR(365/L35,0) -> 36.654418 | N40: =IFERROR(AVERAGE(C40:L40),0) -> 114.35233 | O40: =IFERROR(AVERAGE(D40:M40),0) -> 120.02538
B41: Inventor Days | C41: =IFERROR(365/C36,0) -> 60.435395 | D41: =IFERROR(365/D36,0) -> 61.495222 | E41: =IFERROR(365/E36,0) -> 58.328335 | F41: =IFERROR(365/F36,0) -> 68.970379 | G41: =IFERROR(365/G36,0) -> 63.640827 | H41: =IFERROR(365/H36,0) -> 60.302646 | I41: =IFERROR(365/I36,0) -> 70.417584 | J41: =IFERROR(365/J36,0) -> 60.279325 | ... L41: =IFERROR(365/L36,0) -> 43.563481 | N41: =IFERROR(AVERAGE(C41:L41),0) -> 59.411532 | O41: =IFERROR(AVERAGE(D41:M41),0) -> 59.297769
B42: Cash Conversion Cycle(in days) | C42: =SUM(C39/C41)-C40 -> -63.294923 | D42: =SUM(D39/D41)-D40 -> -56.925019 | E42: =SUM(E39/E41)-E40 -> -59.023635 | F42: =SUM(F39/F41)-F40 -> -57.989548 | G42: =SUM(G39/G41)-G40 -> -295.15388 | H42: =SUM(H39/H41)-H40 -> -437.8457 | I42: =SUM(I39/I41)-I40 -> -51.640443 | J42: =SUM(J39/J41)-J40 -> -45.235767 | ... L42: =SUM(L39/L41)-L40 -> -36.619042 | N42: =IFERROR(AVERAGE(C42:L42),0) -> -114.32442 | O42: =IFERROR(AVERAGE(D42:M42),0) -> -119.99437
B44: CFO/Sales | C44: =IFERROR(HistoricalFS!C88/HistoricalFS!C10,0) -> 1.4482525 | D44: =IFERROR(HistoricalFS!D88/HistoricalFS!D10,0) -> 0.51036172 | E44: =IFERROR(HistoricalFS!E88/HistoricalFS!E10,0) -> 0.94231179 | F44: =IFERROR(HistoricalFS!F88/HistoricalFS!F10,0) -> 0.7828183 | G44: =IFERROR(HistoricalFS!G88/HistoricalFS!G10,0) -> 0.7762523 | H44: =IFERROR(HistoricalFS!H88/HistoricalFS!H10,0) -> 1.3409385 | I44: =IFERROR(HistoricalFS!I88/HistoricalFS!I10,0) -> -0.40195464 | J44: =IFERROR(HistoricalFS!J88/HistoricalFS!J10,0) -> 0.41518948 | ... L44: =IFERROR(HistoricalFS!L88/HistoricalFS!L10,0) -> 0.22498324 | N44: =IFERROR(AVERAGE(C44:L44),0) -> 0.65332095 | O44: =IFERROR(AVERAGE(D44:M44),0) -> 0.56499522
B45: CFO/Total Assests | C45: =IFERROR(HistoricalFS!C88/HistoricalFS!C74,0) -> 1.1323432 | D45: =IFERROR(HistoricalFS!D88/HistoricalFS!D74,0) -> 0.4162448 | E45: =IFERROR(HistoricalFS!E88/HistoricalFS!E74,0) -> 0.87034326 | F45: =IFERROR(HistoricalFS!F88/HistoricalFS!F74,0) -> 0.80468665 | G45: =IFERROR(HistoricalFS!G88/HistoricalFS!G74,0) -> 0.49140317 | H45: =IFERROR(HistoricalFS!H88/HistoricalFS!H74,0) -> 0.607471 | I45: =IFERROR(HistoricalFS!I88/HistoricalFS!I74,0) -> -0.23401441 | J45: =IFERROR(HistoricalFS!J88/HistoricalFS!J74,0) -> 0.42343467 | ... L45: =IFERROR(HistoricalFS!L88/HistoricalFS!L74,0) -> 0.40925131 | N45: =IFERROR(AVERAGE(C45:L45),0) -> 0.57748656 | O45: =IFERROR(AVERAGE(D45:M45),0) -> 0.51583582
C46: =IFERROR(HistoricalFS!C88/HistoricalFS!C59,0) -> 6.108054 | D46: =IFERROR(HistoricalFS!D88/HistoricalFS!D59,0) -> 2.36126 | E46: =IFERROR(HistoricalFS!E88/HistoricalFS!E59,0) -> 5.1937767 | F46: =IFERROR(HistoricalFS!F88/HistoricalFS!F59,0) -> 4.1668353 | G46: =IFERROR(HistoricalFS!G88/HistoricalFS!G59,0) -> 9.0278241 | H46: =IFERROR(HistoricalFS!H88/HistoricalFS!H59,0) -> 11.592705 | I46: =IFERROR(HistoricalFS!I88/HistoricalFS!I59,0) -> -0.38261635 | J46: =IFERROR(HistoricalFS!J88/HistoricalFS!J59,0) -> 0.76655302 | ... L46: =IFERROR(HistoricalFS!L88/HistoricalFS!L59,0) -> 1.7231438 | N46: =IFERROR(AVERAGE(C46:L46),0) -> 4.4045291 | O46: =IFERROR(AVERAGE(D46:M46),0) -> 4.2152485

Sheet Forcasting
B4: ='Ration Analysis'!B4 -> TRENT LTD
B5: ='Ration Analysis'!B5 -> ( TRENT | BSE Code: 500251)
B7: ='Data Sheet'!B1&" - "&'Data Sheet'!A42 -> TRENT LTD - Sales | G7: ='Data Sheet'!B1&" - "&HistoricalFS!B22 -> TRENT LTD - EBITDA | L7: ='Data Sheet'!B1&" - "&HistoricalFS!B45 -> TRENT LTD - EPS
B9: Years Weight | C9: Year | D9: Sales | E9: Sales Growth | G9: Years Weight | H9: Year | I9: =HistoricalFS!B22 -> EBITDA | J9: EBITDA Growth | L9: Years Weight | M9: Year | N9: =HistoricalFS!B45 -> EPS | O9: EPS Growth
B11: 1 | C11: 2016 | D11: {=TRANSPOSE('Data Sheet'!B17:K17)} -> 1686.17 | G11: 1 | H11: 2016 | I11: {=TRANSPOSE(HistoricalFS!C22:L22)} -> 89.76 | L11: 1 | M11: 2016 | N11: {=TRANSPOSE(HistoricalFS!C45:L45)} -> -0.94101715
B12: =B11+1 -> 2 | C12: =C11+1 -> 2017 | D12: 1812.44 | E12: =D12/D11-1 -> 0.074885688 | G12: =G11+1 -> 2 | H12: =H11+1 -> 2017 | I12: 133.53 | J12: =I12/I11-1 -> 0.48763369 | L12: =L11+1 -> 2 | M12: =M11+1 -> 2017 | N12: 0.10953957 | O12: =N12/N11-1 -> -1.1164055
B13: =B12+1 -> 3 | C13: =C12+1 -> 2018 | D13: 2157.46 | E13: =D13/D12-1 -> 0.19036216 | G13: =G12+1 -> 3 | H13: =H12+1 -> 2018 | I13: 208.5 | J13: =I13/I12-1 -> 0.56144687 | L13: =L12+1 -> 3 | M13: =M12+1 -> 2018 | N13: 1.7926572 | O13: =N13/N12-1 -> 15.365385
B14: =B13+1 -> 4 | C14: =C13+1 -> 2019 | D14: 2630.24 | E14: =D14/D13-1 -> 0.21913732 | G14: =G13+1 -> 4 | H14: =H13+1 -> 2019 | I14: 240.64 | J14: =I14/I13-1 -> 0.15414868 | L14: =L13+1 -> 4 | M14: =M13+1 -> 2019 | N14: 1.9476377 | O14: =N14/N13-1 -> 0.086452913
B15: =B14+1 -> 5 | C15: =C14+1 -> 2020 | D15: 3485.98 | E15: =D15/D14-1 -> 0.32534674 | G15: =G14+1 -> 5 | H15: =H14+1 -> 2020 | I15: 528.97 | J15: =I15/I14-1 -> 1.1981799 | L15: =L14+1 -> 5 | M15: =M14+1 -> 2020 | N15: -1.1434599 | O15: =N15/N14-1 -> -1.5871009
B16: =B15+1 -> 6 | C16: =C15+1 -> 2021 | D16: 2592.96 | E16: =D16/D15-1 -> -0.25617473 | G16: =G15+1 -> 6 | H16: =H15+1 -> 2021 | I16: 113.87 | J16: =I16/I15-1 -> -0.78473259 | L16: =L15+1 -> 6 | M16: =M15+1 -> 2021 | N16: -10.704079 | O16: =N16/N15-1 -> 8.3611316
B17: =B16+1 -> 7 | C17: =C16+1 -> 2022 | D17: 4498.02 | E17: =D17/D16-1 -> 0.73470474 | G17: =G16+1 -> 7 | H17: =H16+1 -> 2022 | I17: 594.72 | J17: =I17/I16-1 -> 4.2227979 | L17: =L16+1 -> 7 | M17: =M16+1 -> 2022 | N17: -3.3068917 | O17: =N17/N16-1 -> -0.69106247
B18: =B17+1 -> 8 | C18: =C17+1 -> 2023 | D18: 8242.02 | E18: =D18/D17-1 -> 0.83236624 | G18: =G17+1 -> 8 | H18: =H17+1 -> 2023 | I18: 1114.15 | J18: =I18/I17-1 -> 0.87340261 | L18: =L17+1 -> 8 | M18: =M17+1 -> 2023 | N18: 1.4917018 | O18: =N18/N17-1 -> -1.4510888
B19: =B18+1 -> 9 | C19: =C18+1 -> 2024 | D19: 12375.11 | E19: =D19/D18-1 -> 0.50146566 | G19: =G18+1 -> 9 | H19: =H18+1 -> 2024 | I19: 1970.69 | J19: =I19/I18-1 -> 0.76878338 | L19: =L18+1 -> 9 | M19: =M18+1 -> 2024 | N19: 13.742616 | O19: =N19/N18-1 -> 8.2127098
B20: =B19+1 -> 10 | C20: =C19+1 -> 2025 | D20: 17134.61 | E20: =D20/D19-1 -> 0.38460264 | G20: =G19+1 -> 10 | H20: =H19+1 -> 2025 | I20: 2819.96 | J20: =I20/I19-1 -> 0.43095058 | L20: =L19+1 -> 10 | M20: =M19+1 -> 2025 | N20: 34.580872 | O20: =N20/N19-1 -> 1.5163238
B21: =B20+1 -> 11 | C21: =C20+1 -> 2026 | D21: =FORECAST(B21,$D$11:$D$20,$B$11:$B$20) -> 13931.76 | E21: =D21/D20-1 -> -0.18692284 | G21: =G20+1 -> 11 | H21: =H20+1 -> 2026 | I21: =FORECAST(G21,$I$11:$I$20,$G$11:$G$20) -> 2201.7227 | J21: =I21/I20-1 -> -0.21923621 | L21: =L20+1 -> 11 | M21: =M20+1 -> 2026 | N21: =FORECAST(L21,$N$11:$N$20,$L$11:$L$20) -> 16.700276 | O21: =N21/N20-1 -> -0.51706608
B22: =B21+1 -> 12 | C22: =C21+1 -> 2027 | D22: =FORECAST(B22,$D$11:$D$20,$B$11:$B$20) -> 15435.443 | E22: =D22/D21-1 -> 0.10793205 | G22: =G21+1 -> 12 | H22: =H21+1 -> 2027 | I22: =FORECAST(G22,$I$11:$I$20,$G$11:$G$20) -> 2459.9488 | J22: =I22/I21-1 -> 0.11728367 | L22: =L21+1 -> 12 | M22: =M21+1 -> 2027 | N22: =FORECAST(L22,$N$11:$N$20,$L$11:$L$20) -> 19.053607 | O22: =N22/N21-1 -> 0.14091567
B23: =B22+1 -> 13 | C23: =C22+1 -> 2028 | D23: =FORECAST(B23,$D$11:$D$20,$B$11:$B$20) -> 16939.127 | E23: =D23/D22-1 -> 0.097417574 | G23: =G22+1 -> 13 | H23: =H22+1 -> 2028 | I23: =FORECAST(G23,$I$11:$I$20,$G$11:$G$20) -> 2718.1749 | J23: =I23/I22-1 -> 0.10497215 | L23: =L22+1 -> 13 | M23: =M22+1 -> 2028 | N23: =FORECAST(L23,$N$11:$N$20,$L$11:$L$20) -> 21.406937 | O23: =N23/N22-1 -> 0.12351103
B24: =B23+1 -> 14 | C24: =C23+1 -> 2029 | D24: =FORECAST(B24,$D$11:$D$20,$B$11:$B$20) -> 18442.81 | E24: =D24/D23-1 -> 0.088769832 | G24: =G23+1 -> 14 | H24: =H23+1 -> 2029 | I24: =FORECAST(G24,$I$11:$I$20,$G$11:$G$20) -> 2976.401 | J24: =I24/I23-1 -> 0.094999818 | L24: =L23+1 -> 14 | M24: =M23+1 -> 2029 | N24: =FORECAST(L24,$N$11:$N$20,$L$11:$L$20) -> 23.760268 | O24: =N24/N23-1 -> 0.10993308
B25: =B24+1 -> 15 | C25: =C24+1 -> 2030 | D25: =FORECAST(B25,$D$11:$D$20,$B$11:$B$20) -> 19946.494 | E25: =D25/D24-1 -> 0.08153223 | G25: =G24+1 -> 15 | H25: =H24+1 -> 2030 | I25: =FORECAST(G25,$I$11:$I$20,$G$11:$G$20) -> 3234.6272 | J25: =I25/I24-1 -> 0.086757839 | L25: =L24+1 -> 15 | M25: =M24+1 -> 2030 | N25: =FORECAST(L25,$N$11:$N$20,$L$11:$L$20) -> 26.113599 | O25: =N25/N24-1 -> 0.099044785

Sheet Common Size Statement 
B4: ='Altman Z Score'!B3 -> TRENT LTD
B5: ='Dupont Analysis'!B4 -> ( TRENT | BSE Code: 500251)
B7: ="Common Size Incom Statement"&" - "&'Data Sheet'!$B$1 -> Common Size Incom Statement - TRENT LTD
B9: Particulars | C9: ='Data Sheet'!B56 -> 42460 | D9: ='Data Sheet'!C56 -> 42825 | E9: ='Data Sheet'!D56 -> 43190 | F9: ='Data Sheet'!E56 -> 43555 | G9: ='Data Sheet'!F56 -> 43921 | H9: ='Data Sheet'!G56 -> 44286 | I9: ='Data Sheet'!H56 -> 44651 | J9: ='Data Sheet'!I56 -> 45016 | ... L9: ='Data Sheet'!K56 -> 45747
B11: ='Data Sheet'!A17 -> Sales | C11: ='Data Sheet'!B17/'Data Sheet'!B$17 -> 1 | D11: ='Data Sheet'!C17/'Data Sheet'!C$17 -> 1 | E11: ='Data Sheet'!D17/'Data Sheet'!D$17 -> 1 | F11: ='Data Sheet'!E17/'Data Sheet'!E$17 -> 1 | G11: ='Data Sheet'!F17/'Data Sheet'!F$17 -> 1 | H11: ='Data Sheet'!G17/'Data Sheet'!G$17 -> 1 | I11: ='Data Sheet'!H17/'Data Sheet'!H$17 -> 1 | J11: ='Data Sheet'!I17/'Data Sheet'!I$17 -> 1 | ... L11: ='Data Sheet'!K17/'Data Sheet'!K$17 -> 1
B12: ='Data Sheet'!A18 -> Raw Material Cost | C12: ='Data Sheet'!B18/'Data Sheet'!B$17 -> 0.48049722 | D12: ='Data Sheet'!C18/'Data Sheet'!C$17 -> 0.50275871 | E12: ='Data Sheet'!D18/'Data Sheet'!D$17 -> 0.49596285 | F12: ='Data Sheet'!E18/'Data Sheet'!E$17 -> 0.55495696 | G12: ='Data Sheet'!F18/'Data Sheet'!F$17 -> 0.55985404 | H12: ='Data Sheet'!G18/'Data Sheet'!G$17 -> 0.52898618 | I12: ='Data Sheet'!H18/'Data Sheet'!H$17 -> 0.64925901 | J12: ='Data Sheet'!I18/'Data Sheet'!I$17 -> 0.63225399 | ... L12: ='Data Sheet'!K18/'Data Sheet'!K$17 -> 0.59198254
B13: ='Data Sheet'!A19 -> Change in Inventory | C13: ='Data Sheet'!B19/'Data Sheet'!B$17 -> 0.0086527456 | D13: ='Data Sheet'!C19/'Data Sheet'!C$17 -> 0.016475028 | E13: ='Data Sheet'!D19/'Data Sheet'!D$17 -> 0.017849694 | F13: ='Data Sheet'!E19/'Data Sheet'!E$17 -> 0.056356074 | G13: ='Data Sheet'!F19/'Data Sheet'!F$17 -> 0.020048882 | H13: ='Data Sheet'!G19/'Data Sheet'!G$17 -> -0.062615698 | I13: ='Data Sheet'!H19/'Data Sheet'!H$17 -> 0.097562928 | J13: ='Data Sheet'!I19/'Data Sheet'!I$17 -> 0.059610387 | ... L13: ='Data Sheet'!K19/'Data Sheet'!K$17 -> 0.026510671
B14: ='Data Sheet'!A20 -> Power and Fuel | C14: ='Data Sheet'!B20/'Data Sheet'!B$17 -> 0.029012496 | D14: ='Data Sheet'!C20/'Data Sheet'!C$17 -> 0.02829335 | E14: ='Data Sheet'!D20/'Data Sheet'!D$17 -> 0.024450048 | F14: ='Data Sheet'!E20/'Data Sheet'!E$17 -> 0.022499848 | G14: ='Data Sheet'!F20/'Data Sheet'!F$17 -> 0.019116576 | H14: ='Data Sheet'!G20/'Data Sheet'!G$17 -> 0.019055442 | I14: ='Data Sheet'!H20/'Data Sheet'!H$17 -> 0.015982588 | J14: ='Data Sheet'!I20/'Data Sheet'!I$17 -> 0.017505417 | ... L14: ='Data Sheet'!K20/'Data Sheet'!K$17 -> 0.020418907
B15: ='Data Sheet'!A21 -> Other Mfr. Exp | C15: ='Data Sheet'!B21/'Data Sheet'!B$17 -> 0.045321646 | D15: ='Data Sheet'!C21/'Data Sheet'!C$17 -> 0.04519322 | E15: ='Data Sheet'!D21/'Data Sheet'!D$17 -> 0.042077258 | F15: ='Data Sheet'!E21/'Data Sheet'!E$17 -> 0.046417817 | G15: ='Data Sheet'!F21/'Data Sheet'!F$17 -> 0.027972048 | H15: ='Data Sheet'!G21/'Data Sheet'!G$17 -> 0.035480686 | I15: ='Data Sheet'!H21/'Data Sheet'!H$17 -> 0.02826577 | J15: ='Data Sheet'!I21/'Data Sheet'!I$17 -> 0.025720636 | ... L15: ='Data Sheet'!K21/'Data Sheet'!K$17 -> 0.021581466
B16: ='Data Sheet'!A22 -> Employee Cost | C16: ='Data Sheet'!B22/'Data Sheet'!B$17 -> 0.098264113 | D16: ='Data Sheet'!C22/'Data Sheet'!C$17 -> 0.10743528 | E16: ='Data Sheet'!D22/'Data Sheet'!D$17 -> 0.10800664 | F16: ='Data Sheet'!E22/'Data Sheet'!E$17 -> 0.10983408 | G16: ='Data Sheet'!F22/'Data Sheet'!F$17 -> 0.10356055 | H16: ='Data Sheet'!G22/'Data Sheet'!G$17 -> 0.11700913 | I16: ='Data Sheet'!H22/'Data Sheet'!H$17 -> 0.089577192 | J16: ='Data Sheet'!I22/'Data Sheet'!I$17 -> 0.07996462 | ... L16: ='Data Sheet'!K22/'Data Sheet'!K$17 -> 0.076776769
B17: ='Data Sheet'!A23 -> Selling and admin | C17: ='Data Sheet'!B23/'Data Sheet'!B$17 -> 0.26335423 | D17: ='Data Sheet'!C23/'Data Sheet'!C$17 -> 0.22459778 | E17: ='Data Sheet'!D23/'Data Sheet'!D$17 -> 0.20886135 | F17: ='Data Sheet'!E23/'Data Sheet'!E$17 -> 0.19557531 | G17: ='Data Sheet'!F23/'Data Sheet'!F$17 -> 0.12530766 | H17: ='Data Sheet'!G23/'Data Sheet'!G$17 -> 0.14061922 | I17: ='Data Sheet'!H23/'Data Sheet'!H$17 -> 0.1567423 | J17: ='Data Sheet'!I23/'Data Sheet'!I$17 -> 0.15196881 | ... L17: ='Data Sheet'!K23/'Data Sheet'!K$17 -> 0.13556363
B18: ='Data Sheet'!A24 -> Other Expenses | C18: ='Data Sheet'!B24/'Data Sheet'!B$17 -> 0.038969973 | D18: ='Data Sheet'!C24/'Data Sheet'!C$17 -> 0.034522522 | E18: ='Data Sheet'!D24/'Data Sheet'!D$17 -> 0.041850139 | F18: ='Data Sheet'!E24/'Data Sheet'!E$17 -> 0.035582304 | G18: ='Data Sheet'!F24/'Data Sheet'!F$17 -> 0.032495884 | H18: ='Data Sheet'!G24/'Data Sheet'!G$17 -> 0.052318586 | I18: ='Data Sheet'!H24/'Data Sheet'!H$17 -> 0.025517895 | J18: ='Data Sheet'!I24/'Data Sheet'!I$17 -> 0.017017673 | ... L18: ='Data Sheet'!K24/'Data Sheet'!K$17 -> 0.01561051
B19: ='Data Sheet'!A25 -> Other Income | C19: ='Data Sheet'!B25/'Data Sheet'!B$17 -> 0.051264107 | D19: ='Data Sheet'!C25/'Data Sheet'!C$17 -> 0.044862175 | E19: ='Data Sheet'!D25/'Data Sheet'!D$17 -> 0.012732565 | F19: ='Data Sheet'!E25/'Data Sheet'!E$17 -> 0.01145903 | G19: ='Data Sheet'!F25/'Data Sheet'!F$17 -> 0.042062777 | H19: ='Data Sheet'!G25/'Data Sheet'!G$17 -> 0.076900531 | I19: ='Data Sheet'!H25/'Data Sheet'!H$17 -> 0.033828218 | J19: ='Data Sheet'!I25/'Data Sheet'!I$17 -> 0.041324821 | ... L19: ='Data Sheet'!K25/'Data Sheet'!K$17 -> 0.017803732
B20: ='Data Sheet'!A26 -> Depreciation | C20: ='Data Sheet'!B26/'Data Sheet'!B$17 -> 0.022886186 | D20: ='Data Sheet'!C26/'Data Sheet'!C$17 -> 0.022781444 | E20: ='Data Sheet'!D26/'Data Sheet'!D$17 -> 0.02110352 | F20: ='Data Sheet'!E26/'Data Sheet'!E$17 -> 0.019644595 | G20: ='Data Sheet'!F26/'Data Sheet'!F$17 -> 0.070924102 | H20: ='Data Sheet'!G26/'Data Sheet'!G$17 -> 0.099230223 | I20: ='Data Sheet'!H26/'Data Sheet'!H$17 -> 0.069101516 | J20: ='Data Sheet'!I26/'Data Sheet'!I$17 -> 0.059899151 | ... L20: ='Data Sheet'!K26/'Data Sheet'!K$17 -> 0.052243967
B21: ='Data Sheet'!A27 -> Interest | C21: ='Data Sheet'!B27/'Data Sheet'!B$17 -> 0.028306754 | D21: ='Data Sheet'!C27/'Data Sheet'!C$17 -> 0.025131866 | E21: ='Data Sheet'!D27/'Data Sheet'!D$17 -> 0.020292381 | F21: ='Data Sheet'!E27/'Data Sheet'!E$17 -> 0.019252996 | G21: ='Data Sheet'!F27/'Data Sheet'!F$17 -> 0.075551208 | H21: ='Data Sheet'!G27/'Data Sheet'!G$17 -> 0.10057618 | I21: ='Data Sheet'!H27/'Data Sheet'!H$17 -> 0.072218443 | J21: ='Data Sheet'!I27/'Data Sheet'!I$17 -> 0.049622544 | ... L21: ='Data Sheet'!K27/'Data Sheet'!K$17 -> 0.011678118
B22: ='Data Sheet'!A28 -> Profit before tax | C22: ='Data Sheet'!B28/'Data Sheet'!B$17 -> 0.053304234 | D22: ='Data Sheet'!C28/'Data Sheet'!C$17 -> 0.070623028 | E22: ='Data Sheet'!D28/'Data Sheet'!D$17 -> 0.067978085 | F22: ='Data Sheet'!E28/'Data Sheet'!E$17 -> 0.064051189 | G22: ='Data Sheet'!F28/'Data Sheet'!F$17 -> 0.047329589 | H22: ='Data Sheet'!G28/'Data Sheet'!G$17 -> -0.078990806 | I22: ='Data Sheet'!H28/'Data Sheet'!H$17 -> 0.024726435 | J22: ='Data Sheet'!I28/'Data Sheet'!I$17 -> 0.066982366 | ... L22: ='Data Sheet'!K28/'Data Sheet'!K$17 -> 0.11845849
... B25: ='Data Sheet'!A31 -> Dividend Amount | C25: ='Data Sheet'!B31/'Data Sheet'!B$17 -> 0.017738425 | D25: ='Data Sheet'!C31/'Data Sheet'!C$17 -> 0.0183344 | E25: ='Data Sheet'!D31/'Data Sheet'!D$17 -> 0.017710641 | F25: ='Data Sheet'!E31/'Data Sheet'!E$17 -> 0.016424357 | G25: ='Data Sheet'!F31/'Data Sheet'!F$17 -> 0.010197993 | H25: ='Data Sheet'!G31/'Data Sheet'!G$17 -> 0.00822612 | I25: ='Data Sheet'!H31/'Data Sheet'!H$17 -> 0.013437023 | J25: ='Data Sheet'!I31/'Data Sheet'!I$17 -> 0.0094891786 | ... L25: ='Data Sheet'!K31/'Data Sheet'!K$17 -> 0.0045644459
B26: ='Data Sheet'!A33 -> EBITDA | C26: ='Data Sheet'!B33/'Data Sheet'!B$17 -> 0.10445566 | D26: ='Data Sheet'!C33/'Data Sheet'!C$17 -> 0.11848668 | E26: ='Data Sheet'!D33/'Data Sheet'!D$17 -> 0.10934154 | F26: ='Data Sheet'!E33/'Data Sheet'!E$17 -> 0.10374719 | G26: ='Data Sheet'!F33/'Data Sheet'!F$17 -> 0.19864428 | H26: ='Data Sheet'!G33/'Data Sheet'!G$17 -> 0.13429825 | I26: ='Data Sheet'!H33/'Data Sheet'!H$17 -> 0.18188225 | J26: ='Data Sheet'!I33/'Data Sheet'!I$17 -> 0.18269186 | K26: ='Data Sheet'!J33/'Data Sheet'!J$17 -> 0.23991221 | L26: ='Data Sheet'!K32/'Data Sheet'!K$17 -> 0
B28: ="Common Size Balance Sheet"&" - "&'Data Sheet'!$B$1 -> Common Size Balance Sheet - TRENT LTD
B30: Particulars | C30: =C9 -> 42460 | D30: =D9 -> 42825 | E30: =E9 -> 43190 | F30: =F9 -> 43555 | G30: =G9 -> 43921 | H30: =H9 -> 44286 | I30: =I9 -> 44651 | J30: =J9 -> 45016 | ... L30: =L9 -> 45747
B32: Total Liabilities | C32: ='Data Sheet'!B61/'Data Sheet'!B$61 -> 1 | D32: ='Data Sheet'!C61/'Data Sheet'!C$61 -> 1 | E32: ='Data Sheet'!D61/'Data Sheet'!D$61 -> 1 | F32: ='Data Sheet'!E61/'Data Sheet'!E$61 -> 1 | G32: ='Data Sheet'!F61/'Data Sheet'!F$61 -> 1 | H32: ='Data Sheet'!G61/'Data Sheet'!G$61 -> 1 | I32: ='Data Sheet'!H61/'Data Sheet'!H$61 -> 1 | J32: ='Data Sheet'!I61/'Data Sheet'!I$61 -> 1 | ... L32: ='Data Sheet'!K61/'Data Sheet'!K$61 -> 1
B33: ='Data Sheet'!A57 -> Equity Share Capital | C33: ='Data Sheet'!B57/'Data Sheet'!B$61 -> 0.015408585 | D33: ='Data Sheet'!C57/'Data Sheet'!C$61 -> 0.014953313 | E33: ='Data Sheet'!D57/'Data Sheet'!D$61 -> 0.014226024 | F33: ='Data Sheet'!E57/'Data Sheet'!E$61 -> 0.012986759 | G33: ='Data Sheet'!F57/'Data Sheet'!F$61 -> 0.0064557955 | H33: ='Data Sheet'!G57/'Data Sheet'!G$61 -> 0.0062109848 | I33: ='Data Sheet'!H57/'Data Sheet'!H$61 -> 0.0046013342 | J33: ='Data Sheet'!I57/'Data Sheet'!I$61 -> 0.0043989195 | ... L33: ='Data Sheet'!K57/'Data Sheet'!K$61 -> 0.0037740296
B34: ='Data Sheet'!A58 -> Reserves | C34: ='Data Sheet'!B58/'Data Sheet'!B$61 -> 0.66362174 | D34: ='Data Sheet'!C58/'Data Sheet'!C$61 -> 0.68149848 | E34: ='Data Sheet'!D58/'Data Sheet'!D$61 -> 0.6687644 | F34: ='Data Sheet'!E58/'Data Sheet'!E$61 -> 0.63049289 | G34: ='Data Sheet'!F58/'Data Sheet'!F$61 -> 0.42715756 | H34: ='Data Sheet'!G58/'Data Sheet'!G$61 -> 0.39790137 | I34: ='Data Sheet'!H58/'Data Sheet'!H$61 -> 0.30137768 | J34: ='Data Sheet'!I58/'Data Sheet'!I$61 -> 0.31676428 | ... L34: ='Data Sheet'!K58/'Data Sheet'!K$61 -> 0.57605068
B35: ='Data Sheet'!A59 -> Borrowings | C35: ='Data Sheet'!B59/'Data Sheet'!B$61 -> 0.18538526 | D35: ='Data Sheet'!C59/'Data Sheet'!C$61 -> 0.1762808 | E35: ='Data Sheet'!D59/'Data Sheet'!D$61 -> 0.16757426 | F35: ='Data Sheet'!E59/'Data Sheet'!E$61 -> 0.19311698 | G35: ='Data Sheet'!F59/'Data Sheet'!F$61 -> 0.054432072 | H35: ='Data Sheet'!G59/'Data Sheet'!G$61 -> 0.052401144 | I35: ='Data Sheet'!H59/'Data Sheet'!H$61 -> 0.61161633 | J35: ='Data Sheet'!I59/'Data Sheet'!I$61 -> 0.55238798 | ... L35: ='Data Sheet'!K59/'Data Sheet'!K$61 -> 0.23750271
B36: ='Data Sheet'!A60 -> Other Liabilities | C36: ='Data Sheet'!B60/'Data Sheet'!B$61 -> 0.13558442 | D36: ='Data Sheet'!C60/'Data Sheet'!C$61 -> 0.12726741 | E36: ='Data Sheet'!D60/'Data Sheet'!D$61 -> 0.14943533 | F36: ='Data Sheet'!E60/'Data Sheet'!E$61 -> 0.16340337 | G36: ='Data Sheet'!F60/'Data Sheet'!F$61 -> 0.51195457 | H36: ='Data Sheet'!G60/'Data Sheet'!G$61 -> 0.5434865 | I36: ='Data Sheet'!H60/'Data Sheet'!H$61 -> 0.082404653 | J36: ='Data Sheet'!I60/'Data Sheet'!I$61 -> 0.12644883 | ... L36: ='Data Sheet'!K60/'Data Sheet'!K$61 -> 0.18267259
B38: Total Assets | C38: ='Data Sheet'!B77/'Data Sheet'!B$77 -> 1 | D38: ='Data Sheet'!C77/'Data Sheet'!C$77 -> 1 | E38: ='Data Sheet'!D77/'Data Sheet'!D$77 -> 1 | F38: ='Data Sheet'!E77/'Data Sheet'!E$77 -> 1 | G38: ='Data Sheet'!F77/'Data Sheet'!F$77 -> 1 | H38: ='Data Sheet'!G77/'Data Sheet'!G$77 -> 1 | I38: ='Data Sheet'!H77/'Data Sheet'!H$77 -> 1 | J38: ='Data Sheet'!I77/'Data Sheet'!I$77 -> 1 | ... L38: ='Data Sheet'!K77/'Data Sheet'!K$77 -> 1
B39: ='Data Sheet'!A62 -> Net Block | C39: ='Data Sheet'!B62/'Data Sheet'!B$77 -> 0.22108514 | D39: ='Data Sheet'!C62/'Data Sheet'!C$77 -> 0.24691641 | E39: ='Data Sheet'!D62/'Data Sheet'!D$77 -> 0.2622289 | F39: ='Data Sheet'!E62/'Data Sheet'!E$77 -> 0.25878941 | G39: ='Data Sheet'!F62/'Data Sheet'!F$77 -> 0.49729238 | H39: ='Data Sheet'!G62/'Data Sheet'!G$77 -> 0.5335367 | I39: ='Data Sheet'!H62/'Data Sheet'!H$77 -> 0.60661375 | J39: ='Data Sheet'!I62/'Data Sheet'!I$77 -> 0.56016002 | ... L39: ='Data Sheet'!K62/'Data Sheet'!K$77 -> 0.41351156
B40: ='Data Sheet'!A63 -> Capital Work in Progress | C40: ='Data Sheet'!B63/'Data Sheet'!B$77 -> 0.025438308 | D40: ='Data Sheet'!C63/'Data Sheet'!C$77 -> 0.0024659692 | E40: ='Data Sheet'!D63/'Data Sheet'!D$77 -> 0.0041055543 | F40: ='Data Sheet'!E63/'Data Sheet'!E$77 -> 0.034071191 | G40: ='Data Sheet'!F63/'Data Sheet'!F$77 -> 0.0042348566 | H40: ='Data Sheet'!G63/'Data Sheet'!G$77 -> 0.01886532 | I40: ='Data Sheet'!H63/'Data Sheet'!H$77 -> 0.013554197 | J40: ='Data Sheet'!I63/'Data Sheet'!I$77 -> 0.012586726 | ... L40: ='Data Sheet'!K63/'Data Sheet'!K$77 -> 0.01905593
B41: ='Data Sheet'!A64 -> Investments | C41: ='Data Sheet'!B64/'Data Sheet'!B$77 -> 0.49474865 | D41: ='Data Sheet'!C64/'Data Sheet'!C$77 -> 0.48597593 | E41: ='Data Sheet'!D64/'Data Sheet'!D$77 -> 0.43790296 | F41: ='Data Sheet'!E64/'Data Sheet'!E$77 -> 0.34502259 | G41: ='Data Sheet'!F64/'Data Sheet'!F$77 -> 0.27508045 | H41: ='Data Sheet'!G64/'Data Sheet'!G$77 -> 0.25984629 | I41: ='Data Sheet'!H64/'Data Sheet'!H$77 -> 0.16615541 | J41: ='Data Sheet'!I64/'Data Sheet'!I$77 -> 0.13733414 | ... L41: ='Data Sheet'!K64/'Data Sheet'!K$77 -> 0.15714507
B42: ='Data Sheet'!A65 -> Other Assets | C42: ='Data Sheet'!B76/'Data Sheet'!B$77 -> 0.1107721 | D42: ='Data Sheet'!C76/'Data Sheet'!C$77 -> 0.10914164 | E42: ='Data Sheet'!D76/'Data Sheet'!D$77 -> 0.1276532 | F42: ='Data Sheet'!E76/'Data Sheet'!E$77 -> 0.14022026 | G42: ='Data Sheet'!F76/'Data Sheet'!F$77 -> 0.098754603 | H42: ='Data Sheet'!G76/'Data Sheet'!G$77 -> 0.095044665 | I42: ='Data Sheet'!H76/'Data Sheet'!H$77 -> 0.087866715 | J42: ='Data Sheet'!I76/'Data Sheet'!I$77 -> 0.10655656 | ... L42: ='Data Sheet'!K76/'Data Sheet'!K$77 -> 0.15042188
B43: ='Data Sheet'!A67 -> Receivables | C43: ='Data Sheet'!B67/'Data Sheet'!B$77 -> 0.006023398 | D43: ='Data Sheet'!C67/'Data Sheet'!C$77 -> 0.0026639667 | E43: ='Data Sheet'!D67/'Data Sheet'!D$77 -> 0.0064644285 | F43: ='Data Sheet'!E67/'Data Sheet'!E$77 -> 0.0064640685 | G43: ='Data Sheet'!F67/'Data Sheet'!F$77 -> 0.0031089513 | H43: ='Data Sheet'!G67/'Data Sheet'!G$77 -> 0.0036287526 | I43: ='Data Sheet'!H67/'Data Sheet'!H$77 -> 0.002363442 | J43: ='Data Sheet'!I67/'Data Sheet'!I$77 -> 0.0042553823 | ... L43: ='Data Sheet'!K67/'Data Sheet'!K$77 -> 0.0066828456
B44: ='Data Sheet'!A68 -> Inventory | C44: ='Data Sheet'!B68/'Data Sheet'!B$77 -> 0.12945901 | D44: ='Data Sheet'!C68/'Data Sheet'!C$77 -> 0.13741028 | E44: ='Data Sheet'!D68/'Data Sheet'!D$77 -> 0.14759874 | F44: ='Data Sheet'!E68/'Data Sheet'!E$77 -> 0.19423862 | G44: ='Data Sheet'!F68/'Data Sheet'!F$77 -> 0.11037685 | H44: ='Data Sheet'!G68/'Data Sheet'!G$77 -> 0.074844551 | I44: ='Data Sheet'!H68/'Data Sheet'!H$77 -> 0.11231915 | J44: ='Data Sheet'!I68/'Data Sheet'!I$77 -> 0.1684285 | ... L44: ='Data Sheet'!K68/'Data Sheet'!K$77 -> 0.2171049
B45: ='Data Sheet'!A69 -> Cash & Bank | C45: ='Data Sheet'!B69/'Data Sheet'!B$77 -> 0.012473395 | D45: ='Data Sheet'!C69/'Data Sheet'!C$77 -> 0.015425807 | E45: ='Data Sheet'!D69/'Data Sheet'!D$77 -> 0.014046219 | F45: ='Data Sheet'!E69/'Data Sheet'!E$77 -> 0.02119386 | G45: ='Data Sheet'!F69/'Data Sheet'!F$77 -> 0.01115191 | H45: ='Data Sheet'!G69/'Data Sheet'!G$77 -> 0.014233725 | I45: ='Data Sheet'!H69/'Data Sheet'!H$77 -> 0.011127333 | J45: ='Data Sheet'!I69/'Data Sheet'!I$77 -> 0.010678671 | ... L45: ='Data Sheet'!K69/'Data Sheet'!K$77 -> 0.036077812

Sheet DCF>

Sheet DCF
B2: ='Intrisic Growth'!B4 -> TRENT LTD
B3: ='Intrisic Growth'!B5 -> ( TRENT | BSE Code: 500251)
B5: Company Overview
B15: Revenue Projections & Growth Assumptions
I16: ₹ in Crores
B18: Year | E18: =E27 -> 46083 | F18: =366+E18 -> 46449 | G18: =366+F18 -> 46815 | H18: =366+G18 -> 47181 | I18: =366+H18 -> 47547
B19: Revenue Growth % | E19: {=CHOOSE(F21,E22:I22,E23:I23,E24:I24)} -> 0.2 | F19: 0.18 | G19: 0.16 | H19: 0.14 | I19: 0.12
B20: Revenue (in Cr) | E20: =D28*(1+E19) -> 20561.532 | F20: =E28*(1+F19) -> 24262.608 | G20: =F28*(1+G19) -> 28144.625 | H20: =G28*(1+H19) -> 32084.873 | I20: =H28*(1+I19) -> 35935.057
B21: Chosen | E21: Base Case | F21: =MATCH(E21,B22:B24) -> 1
B22: Base Case | E22: =WACC!C16 -> 0.2 | F22: =E22-Taper_rate -> 0.18 | G22: =F22-Taper_rate -> 0.16 | H22: =G22-Taper_rate -> 0.14 | I22: =H22-Taper_rate -> 0.12
B23: Best Case | E23: =E22+5% -> 0.25 | F23: =E23-Taper_rate -> 0.23 | G23: =F23-Taper_rate -> 0.21 | H23: =G23-Taper_rate -> 0.19 | I23: =H23-Taper_rate -> 0.17
B24: Worst Case | E24: =E22-5% -> 0.15 | F24: =E24-Taper_rate -> 0.13 | G24: =F24-Taper_rate -> 0.11 | H24: =G24-Taper_rate -> 0.09 | I24: =H24-Taper_rate -> 0.07
B27: Calculation of PV of FCFF | D27: ='Intrisic Growth'!K8 -> 45717 | E27: =366+D27 -> 46083 | F27: =366+E27 -> 46449 | G27: =366+F27 -> 46815 | H27: =366+G27 -> 47181 | I27: =366+H27 -> 47547
B28: Revenue | D28: =HistoricalFS!L10 -> 17134.61 | E28: =E20 -> 20561.532 | F28: =F20 -> 24262.608 | G28: =G20 -> 28144.625 | H28: =H20 -> 32084.873 | I28: =I20 -> 35935.057
B29: EBITDA Margin % | D29: =HistoricalFS!L23 -> 0.16457684 | E29: =D29 -> 0.16457684 | F29: =E29 -> 0.16457684 | G29: =F29 -> 0.16457684 | H29: =G29 -> 0.16457684 | I29: =H29 -> 0.16457684
B30: EBITDA | D30: =D28*D29 -> 2819.96 | E30: =E28*E29 -> 3383.952 | F30: =F28*F29 -> 3993.0634 | G30: =G28*G29 -> 4631.9535 | H30: =H28*H29 -> 5280.427 | I30: =I28*I29 -> 5914.0782
B31: Less: Deperciation | D31: =D28*AVERAGE(HistoricalFS!$H$26:$L$26) -> 1147.0096 | E31: =E28*AVERAGE(HistoricalFS!$H$26:$L$26) -> 1376.4115 | F31: =F28*AVERAGE(HistoricalFS!$H$26:$L$26) -> 1624.1656 | G31: =G28*AVERAGE(HistoricalFS!$H$26:$L$26) -> 1884.0321 | H31: =H28*AVERAGE(HistoricalFS!$H$26:$L$26) -> 2147.7966 | I31: =I28*AVERAGE(HistoricalFS!$H$26:$L$26) -> 2405.5322
B32: EBIT | D32: =HistoricalFS!L28 -> 1924.78 | E32: =E30-E31 -> 2007.5405 | F32: =F30-F31 -> 2368.8978 | G32: =G30-G31 -> 2747.9214 | H32: =H30-H31 -> 3132.6304 | I32: =I30-I31 -> 3508.5461
B33: Tax | D33: =D32*Tax_rate -> 481.195 | E33: =E32*Tax_rate -> 501.88512 | F33: =F32*Tax_rate -> 592.22444 | G33: =G32*Tax_rate -> 686.98035 | H33: =H32*Tax_rate -> 783.1576 | I33: =I32*Tax_rate -> 877.13652 | M33: 46083 | N33: 46449 | O33: 46815 | P33: 47181 | Q33: 47547
B34: NOPAT | D34: =D32-D33 -> 1443.585 | E34: =E32-E33 -> 1505.6554 | F34: =F32-F33 -> 1776.6733 | G34: =G32-G33 -> 2060.9411 | H34: =H32-H33 -> 2349.4728 | I34: =I32-I33 -> 2631.4096 | M34: 2019.4721 | N34: 2382.977 | O34: 2764.2533 | P34: 3151.2488 | Q34: 3529.3987
B35: Add: Deperication | D35: =D31 -> 1147.0096 | E35: =E31 -> 1376.4115 | F35: =F31 -> 1624.1656 | G35: =G31 -> 1884.0321 | H35: =H31 -> 2147.7966 | I35: =I31 -> 2405.5322
B36: Less Reinvestment | D36: =-D34*'Intrisic Growth'!$K$54 -> -827.03451 | E36: =-E34*'Intrisic Growth'!$K$54 -> -862.59483 | F36: =-F34*'Intrisic Growth'!$K$54 -> -1017.8619 | G36: =-G34*'Intrisic Growth'!$K$54 -> -1180.7198 | H36: =-H34*'Intrisic Growth'!$K$54 -> -1346.0206 | I36: =-I34*'Intrisic Growth'!$K$54 -> -1507.543 | M36: 1911.2658 | N36: 2020.0847 | O36: 2098.9112 | P36: 2143.2133 | Q36: 2150.0567
B37: Free Cash Flow of From | D37: =SUM(D34:D36) -> 1763.5601 | E37: =SUM(E34:E36) -> 2019.4721 | F37: =SUM(F34:F36) -> 2382.977 | G37: =SUM(G34:G36) -> 2764.2533 | H37: =SUM(H34:H36) -> 3151.2488 | I37: =SUM(I34:I36) -> 3529.3987
B38: Mid Year Convention | E38: 0.5 | F38: =E38+1 -> 1.5 | G38: =F38+1 -> 2.5 | H38: =G38+1 -> 3.5 | I38: =H38+1 -> 4.5
B39: Discounting Factor | E39: =1/(1+$C$45)^E38 -> 0.94641855 | F39: =1/(1+$C$45)^F38 -> 0.84771474 | G39: =1/(1+$C$45)^G38 -> 0.75930493 | H39: =1/(1+$C$45)^H38 -> 0.68011556 | I39: =1/(1+$C$45)^I38 -> 0.609185
B41: PV of FCFF | E41: =E37*E39 -> 1911.2658 | F41: =F37*F39 -> 2020.0847 | G41: =G37*G39 -> 2098.9112 | H41: =H37*H39 -> 2143.2133 | I41: =I37*I39 -> 2150.0567
B43: Expected Growth | C43: ='Intrisic Growth'!K64 -> 0.24828276
B44: Terminal Growth | C44: =WACC!C18 -> 0.065 | K44: 1
B45: WACC | C45: =WACC!J61 -> 0.11643518 | K45: reinvestment grwot take it from intrisic griwth table as a median
B47: Calulation of Terminal Value | E47: Sensitivity Analysis
B49: FCFF (FY30) | C49: =I37 -> 3529.3987 | E49: Terminal Growth / WACC
B50: WACC | C50: =C45 -> 0.11643518 | E50: =C64 -> 1528.4734 | F50: 0.16 | G50: 0.1164 | H50: 0.18 | I50: 0.19
B51: Terminal Growth Rate | C51: =C44 -> 0.065 | E51: =E52-1% -> 0.04 | F51: 690.34047 | G51: 1099.4358 | H51: 588.38031 | I51: 547.6846
B52: Terminal Value | C52: =C49*(1+C51)/(C50-C51) -> 73078.58 | E52: 0.05 | F52: 735.09887 | G52: 1232.6102 | H52: 618.95717 | I52: 573.41329
E53: =C44 -> 0.065 | F53: 819.90425 | G53: 1529.5319 | H53: 674.79319 | I53: 619.72494
B54: Calulation of Present Value | E54: 0.07 | F54: 854.45459 | G54: 1671.1671 | H54: 696.7892 | I54: 637.73503
E55: =E54+1% -> 0.08 | F55: 936.51165 | G55: 2071.1695 | H55: 747.38002 | I55: 678.66704
B56: PV of FCFF (Fy 26-30) | C56: =SUM(E41:I41) -> 10323.532
B57: PV of Terminal Value | C57: =C52*I39 -> 44518.374
B58: Enterprice Value | C58: =SUM(C56:C57) -> 54841.906
...

Sheet Data>

Sheet WACC
B6: ='Beta-Regression'!B2 -> TRENT LTD
B7: ='Beta-Regression'!B3 -> ( TRENT | BSE Code: 500251)
B9: Weighted Average Cost of Capital
B11: Key Assumptions & Methodology
B13: Parameter | C13: Value | D13: Rationale
B15: Valuation Date | C15: 46067
B16: Revenue Growth% | C16: 0.2 | D16: Based on Management Guidance
C17: 0.02
B18: Terminal Growth Rate | C18: 0.065 | D18: Conservative long term growth considering India's GDP and retail sector potential
B19: Risk-Free Rate (Rf) | C19: 0.0676 | D19: 10-years Government Bond Yield
B20: Equity Risk Premium (ERP) | C20: =12%-C19 -> 0.0524 | D20: Expected return over risk free rate for equity investors
B21: Tax Rate | C21: 0.25 | D21: Effective tax rate based on historical data
B24: Peer Comps
J25: ₹ in Crores
G26: Debt/ | H26: Debt/ | I26: Levered | J26: Unlevered
